path.existsSync is now called `fs.existsSync`.
Application has thrown an uncaught exception and is terminated:
Error: failed to connect to [ds037977.mongolab.com:37977]
    at Server.connect.connectionPool.on.server._serverState (C:\Data\Personal\Work\WebMatrix-folder\BilancioNode\node_modules\mongoose\node_modules\mongodb\lib\mongodb\connection\server.js:569:74)
    at EventEmitter.emit (events.js:115:20)
    at connection.on._self._poolState (C:\Data\Personal\Work\WebMatrix-folder\BilancioNode\node_modules\mongoose\node_modules\mongodb\lib\mongodb\connection\connection_pool.js:139:15)
    at EventEmitter.emit (events.js:91:17)
    at Socket.errorHandler (C:\Data\Personal\Work\WebMatrix-folder\BilancioNode\node_modules\mongoose\node_modules\mongodb\lib\mongodb\connection\connection.js:475:10)
    at Socket.EventEmitter.emit (events.js:88:17)
    at Socket._destroy.self.errorEmitted (net.js:328:14)
    at process.startup.processNextTick.process._tickCallback (node.js:244:9)
